JOB ID Summary:
SLURM_JOBID:  22182545
SLURM_ARRAY_TASK_ID:  9
SLURM_ARRAY_JOB_ID:  22179689
Unable to open file for Java VM logging

                            < M A T L A B (R) >
                  Copyright 1984-2019 The MathWorks, Inc.
                  R2019a (9.6.0.1072779) 64-bit (glnxa64)
                               March 8, 2019

 
To get started, type doc.
For product information, visit www.mathworks.com.
 
{Index exceeds the number of array elements (0).

Error in recall_beta2roi (line 12)
betaFiles = betaidx(scanN);
} 
Traceback (most recent call last):
  File "/home/jeonj1/.conda/envs/py3/lib/python3.6/site-packages/pandas/core/indexes/base.py", line 2656, in get_loc
    return self._engine.get_loc(key)
  File "pandas/_libs/index.pyx", line 108, in pandas._libs.index.IndexEngine.get_loc
  File "pandas/_libs/index.pyx", line 132, in pandas._libs.index.IndexEngine.get_loc
  File "pandas/_libs/hashtable_class_helper.pxi", line 1601, in pandas._libs.hashtable.PyObjectHashTable.get_item
  File "pandas/_libs/hashtable_class_helper.pxi", line 1608, in pandas._libs.hashtable.PyObjectHashTable.get_item
KeyError: 'onset'

During handling of the above exception, another exception occurred:

Traceback (most recent call last):
  File "<string>", line 1, in <module>
  File "/gpfs52/home/jeonj1/proj/cdcat_spm/recall/filter_pads.py", line 29, in filter_pads
    rec_pads = subj_rec.index[subj_rec['onset'] == 0].tolist()
  File "/home/jeonj1/.conda/envs/py3/lib/python3.6/site-packages/pandas/core/frame.py", line 2927, in __getitem__
    indexer = self.columns.get_loc(key)
  File "/home/jeonj1/.conda/envs/py3/lib/python3.6/site-packages/pandas/core/indexes/base.py", line 2658, in get_loc
    return self._engine.get_loc(self._maybe_cast_indexer(key))
  File "pandas/_libs/index.pyx", line 108, in pandas._libs.index.IndexEngine.get_loc
  File "pandas/_libs/index.pyx", line 132, in pandas._libs.index.IndexEngine.get_loc
  File "pandas/_libs/hashtable_class_helper.pxi", line 1601, in pandas._libs.hashtable.PyObjectHashTable.get_item
  File "pandas/_libs/hashtable_class_helper.pxi", line 1608, in pandas._libs.hashtable.PyObjectHashTable.get_item
KeyError: 'onset'
ALL DONE!
